Workbook

Sheet nový výpočet
A1: Tab.1: Podiel osôb, ktorí neboli obmedzovaní kvôli zdravotnému problému v činnostiach, ktoré bežne vykonávajú, podľa krajov SR, EU SILC 2024
B2: Nepriama kalibrácia koeficientu geometrického poklesu pomocou váženého priemeru | I2: Scenár: podiel vo veku 85+ = 0 % | Q2: Scenár: podiel vo veku 85+ = 2,5 % | Y2: Scenár: podiel vo veku 85+ = 5 %
A3: Vôbec neobmedzovaný Kraj | B3: Podiel (v %) - Osoby vo veku | I3: Vôbec neobmedzovaný | J3: Podiel (v %) – osoby vo veku | Q3: Vôbec neobmedzovaný | R3: Podiel (v %) – osoby vo veku | Y3: Vôbec neobmedzovaný | Z3: Podiel (v %) – osoby vo veku
AG4: 5% oproti 0%
B5: 45-54 | C5: 55-64 | D5: 65-74 | E5: 75-84 | F5: 85+ | G5: 55+ | J5: 45–54 | K5: 55–64 | L5: 65–74 | M5: 75–84 | N5: 85+ | O5: 55+ | R5: 45–54 | S5: 55–64 | T5: 65–74 | U5: 75–84 | V5: 85+ | W5: 55+ | Z5: 45–54 | AA5: 55–64 | AB5: 65–74 | AC5: 75–84 | AD5: 85+ | AE5: 55+ | AG5: 65–74 | AH5: 75–84
I6: Kraj | Q6: Kraj | Y6: Kraj
A7: SR | B7: 0.70649273 | C7: 0.495 | D7: 0.32847847 | E7: 0.21797597 | F7: 0.1446473 | G7: 0.36582028 | I7: SR | J7: 0.70649273 | K7: 0.495 | L7: 0.34037209 | M7: 0.23404679 | N7: 0 | O7: 0.36582028 | Q7: SR | R7: 0.70649273 | S7: 0.495 | T7: 0.33832844 | U7: 0.23124472 | V7: 0.025 | W7: 0.36582028 | Y7: SR | Z7: 0.70649273 | AA7: 0.495 | AB7: 0.33627984 | AC7: 0.22845279 | AD7: 0.05 | AE7: 0.36582028
A8: Bratislavský kraj | B8: 0.6787745 | C8: 0.757 | D8: 0.27177151 | E8: 0.097569024 | F8: 0.035028376 | G8: 0.40351654 | I8: Bratislavský kraj | J8: 0.6787745 | K8: 0.757 | L8: 0.27556601 | M8: 0.10031258 | N8: 0 | O8: 0.40351654 | Q8: Bratislavský kraj | R8: 0.6787745 | S8: 0.757 | T8: 0.27285931 | U8: 0.098351654 | V8: 0.025 | W8: 0.40351654 | Y8: Bratislavský kraj | Z8: 0.6787745 | AA8: 0.757 | AB8: 0.2701453 | AC8: 0.096404864 | AD8: 0.05 | AE8: 0.40351654 | AG8: =ABS(L8-AB8) -> 0.005420712 | AH8: =ABS(M8-AC8) -> 0.0039077197
A9: Trnavský kraj | B9: 0.66339689 | C9: 0.431 | D9: 0.35710967 | E9: 0.29588704 | F9: 0.24516038 | G9: 0.3705199 | I9: Trnavský kraj | J9: 0.66339689 | K9: 0.431 | L9: 0.37365259 | M9: 0.32393563 | N9: 0 | O9: 0.3705199 | Q9: Trnavský kraj | R9: 0.66339689 | S9: 0.431 | T9: 0.37198103 | U9: 0.32104382 | V9: 0.025 | W9: 0.3705199 | Y9: Trnavský kraj | Z9: 0.66339689 | AA9: 0.431 | AB9: 0.37030603 | AC9: 0.31815907 | AD9: 0.05 | AE9: 0.3705199 | AG9: =ABS(L9-AB9) -> 0.003346556 | AH9: =ABS(M9-AC9) -> 0.0057765643
A10: Trenčiansky kraj | B10: 0.71935162 | C10: 0.573 | D10: 0.35041877 | E10: 0.21429897 | F10: 0.13105477 | G10: 0.40117176 | I10: Trenčiansky kraj | J10: 0.71935162 | K10: 0.573 | L10: 0.36183844 | M10: 0.228494 | N10: 0 | O10: 0.40117176 | Q10: Trenčiansky kraj | R10: 0.71935162 | S10: 0.573 | T10: 0.35967079 | U10: 0.22576453 | V10: 0.025 | W10: 0.40117176 | Y10: Trenčiansky kraj | Z10: 0.71935162 | AA10: 0.573 | AB10: 0.3574981 | AC10: 0.22304518 | AD10: 0.05 | AE10: 0.40117176 | AG10: =ABS(L10-AB10) -> 0.0043403485 | AH10: =ABS(M10-AC10) -> 0.0054488154
A11: Nitriansky kraj | B11: 0.79012554 | C11: 0.651 | D11: 0.4407986 | E11: 0.29846913 | F11: 0.20209643 | G11: 0.48681538 | I11: Nitriansky kraj | J11: 0.79012554 | K11: 0.651 | L11: 0.4567816 | M11: 0.32050604 | N11: 0 | O11: 0.48681538 | Q11: Nitriansky kraj | R11: 0.79012554 | S11: 0.651 | T11: 0.45481682 | U11: 0.31775474 | V11: 0.025 | W11: 0.48681538 | Y11: Nitriansky kraj | Z11: 0.79012554 | AA11: 0.651 | AB11: 0.45284857 | AC11: 0.31501049 | AD11: 0.05 | AE11: 0.48681538 | AG11: =ABS(L11-AB11) -> 0.0039330301 | AH11: =ABS(M11-AC11) -> 0.0054955498
A12: Žilinský kraj | B12: 0.75713537 | C12: 0.349 | D12: 0.26636294 | E12: 0.20329288 | F12: 0.1551567 | G12: 0.28354339 | I12: Žilinský kraj | J12: 0.75713537 | K12: 0.349 | L12: 0.27822988 | M12: 0.2218105 | N12: 0 | O12: 0.28354339 | Q12: Žilinský kraj | R12: 0.75713537 | S12: 0.349 | T12: 0.2763326 | U12: 0.21879572 | V12: 0.025 | W12: 0.28354339 | Y12: Žilinský kraj | Z12: 0.75713537 | AA12: 0.349 | AB12: 0.27442971 | AC12: 0.21579273 | AD12: 0.05 | AE12: 0.28354339 | AG12: =ABS(L12-AB12) -> 0.003800172 | AH12: =ABS(M12-AC12) -> 0.0060177694
A13: Banskobystrický kraj | B13: 0.76795152 | C13: 0.487 | D13: 0.3339243 | E13: 0.22896394 | F13: 0.15699512 | G13: 0.36824203 | I13: Banskobystrický kraj | J13: 0.76795152 | K13: 0.487 | L13: 0.34607583 | M13: 0.24593117 | N13: 0 | O13: 0.36824203 | Q13: Banskobystrický kraj | R13: 0.76795152 | S13: 0.487 | T13: 0.34415253 | U13: 0.24320527 | V13: 0.025 | W13: 0.36824203 | Y13: Banskobystrický kraj | Z13: 0.76795152 | AA13: 0.487 | AB13: 0.34222484 | AC13: 0.24048838 | AD13: 0.05 | AE13: 0.36824203 | AG13: =ABS(L13-AB13) -> 0.0038509902 | AH13: =ABS(M13-AC13) -> 0.0054427909
A14: Prešovský kraj | B14: 0.68840596 | C14: 0.288 | D14: 0.2108929 | E14: 0.15442991 | F14: 0.11308393 | G14: 0.22859565 | I14: Prešovský kraj | J14: 0.68840596 | K14: 0.288 | L14: 0.22009731 | M14: 0.16820425 | N14: 0 | O14: 0.22859565 | Q14: Prešovský kraj | R14: 0.68840596 | S14: 0.288 | T14: 0.21807645 | U14: 0.16512965 | V14: 0.025 | W14: 0.22859565 | Y14: Prešovský kraj | Z14: 0.68840596 | AA14: 0.288 | AB14: 0.21604773 | AC14: 0.1620716 | AD14: 0.05 | AE14: 0.22859565 | AG14: =ABS(L14-AB14) -> 0.0040495788 | AH14: =ABS(M14-AC14) -> 0.0061326517
A15: Košický kraj | B15: 0.59957411 | C15: 0.5 | D15: 0.34025199 | E15: 0.23154283 | F15: 0.15756582 | G15: 0.37664575 | I15: Košický kraj | J15: 0.59957411 | K15: 0.5 | L15: 0.35362208 | M15: 0.25009715 | N15: 0 | O15: 0.37664575 | Q15: Košický kraj | R15: 0.59957411 | S15: 0.5 | T15: 0.35151447 | U15: 0.24712484 | V15: 0.025 | W15: 0.37664575 | Y15: Košický kraj | Z15: 0.59957411 | AA15: 0.5 | AB15: 0.34940173 | AC15: 0.24416313 | AD15: 0.05 | AE15: 0.37664575 | AG15: =ABS(L15-AB15) -> 0.0042203544 | AH15: =ABS(M15-AC15) -> 0.0059340192
Y16: Priemerná absolútna zmena | AD16: maximálna zmena
Y17: veková skupina | Z17: priemerná absolútna zmena | AD17: maximálna zmena
Y18: 65-74 | Z18: =AVERAGE(AG8:AG15) -> 0.0041202178 | AD18: =MAX(AG8:AG15) -> 0.005420712
Y19: 75-84 | Z19: =AVERAGE(AH8:AH15) -> 0.005519485 | AD19: =MAX(AH8:AH15) -> 0.0061326517
A21: Tab.2: Podiel mužov, ktorí neboli obmedzovaní kvôli zdravotnému problému v činnostiach, ktoré bežne vykonávajú, podľa krajov SR, EU SILC 2024
I22: Scenár: podiel vo veku 85+ = 0 % | Q22: Scenár: podiel vo veku 85+ = 2,5 % | Y22: Scenár: podiel vo veku 85+ = 5 %
A23: Vôbec neobmedzovaný Kraj | B23: Podiel (v %) - Muži vo veku | I23: Vôbec neobmedzovaný | J23: Podiel (v %) – muži vo veku | Q23: Vôbec neobmedzovaný | R23: Podiel (v %) – muži vo veku | Y23: Vôbec neobmedzovaný | Z23: Podiel (v %) – muži vo veku
AG24: 5% oproti 0%
B25: 45-54 | C25: 55-64 | D25: 65-74 | E25: 75-84 | F25: 85+ | G25: 55+ | J25: 45–54 | K25: 55–64 | L25: 65–74 | M25: 75–84 | N25: 85+ | O25: 55+ | R25: 45–54 | S25: 55–64 | T25: 65–74 | U25: 75–84 | V25: 85+ | W25: 55+ | Z25: 45–54 | AA25: 55–64 | AB25: 65–74 | AC25: 75–84 | AD25: 85+ | AE25: 55+ | AG25: 65–74 | AH25: 75–84
H26: r_T=y_(75-84)/y_(65-74) =18,7/38,8=0,48196 | I26: Kraj | Q26: Kraj | Y26: Kraj
A27: SR | B27: 0.71809303 | C27: 0.487 | D27: 0.3152059 | E27: 0.20401388 | F27: 0.13204596 | G27: 0.36844975 | I27: SR | J27: 0.71809303 | K27: 0.487 | L27: 0.32286891 | M27: 0.21405408 | N27: 0 | O27: 0.36844975 | Q27: SR | R27: 0.71809303 | S27: 0.487 | T27: 0.32142298 | U27: 0.21214114 | V27: 0.025 | W27: 0.36844975 | Y27: SR | Z27: 0.71809303 | AA27: 0.487 | AB27: 0.31997478 | AC27: 0.2102338 | AD27: 0.05 | AE27: 0.36844975
A28: Bratislavský kraj | B28: 0.72713545 | C28: 0.772 | D28: 0.20529355 | E28: 0.054592539 | F28: 0.014517482 | G28: 0.40239454 | I28: Bratislavský kraj | J28: 0.72713545 | K28: 0.772 | L28: 0.20658089 | M28: 0.055279358 | N28: 0 | O28: 0.40239454 | Q28: Bratislavský kraj | R28: 0.72713545 | S28: 0.772 | T28: 0.20436303 | U28: 0.054098769 | V28: 0.025 | W28: 0.40239454 | Y28: Bratislavský kraj | Z28: 0.72713545 | AA28: 0.772 | AB28: 0.20214054 | AC28: 0.052928494 | AD28: 0.05 | AE28: 0.40239454 | AG28: =ABS(L28-AB28) -> 0.004440352 | AH28: =ABS(M28-AC28) -> 0.002350864
A29: Trnavský kraj | B29: 0.70126634 | C29: 0.433 | D29: =G29 -> 0.34703407 | E29: 0.2228421 | F29: 0.15986445 | G29: 0.34703407 | I29: Trnavský kraj | J29: 0.70126634 | K29: 0.433 | L29: 0.31856995 | M29: 0.23438063 | N29: 0 | O29: 0.34703407 | Q29: Trnavský kraj | R29: 0.70126634 | S29: 0.433 | T29: 0.31733304 | U29: 0.23256411 | V29: 0.025 | W29: 0.34703407 | Y29: Trnavský kraj | Z29: 0.70126634 | AA29: 0.433 | AB29: 0.31609435 | AC29: 0.23075204 | AD29: 0.05 | AE29: 0.34703407 | AG29: =ABS(L29-AB29) -> 0.0024756031 | AH29: =ABS(M29-AC29) -> 0.0036285841
A30: Trenčiansky kraj | B30: 0.72548897 | C30: 0.557 | D30: =G30 -> 0.39524702 | E30: 0.18690341 | F30: 0.10826754 | G30: 0.39524702 | I30: Trenčiansky kraj | J30: 0.72548897 | K30: 0.557 | L30: 0.32938999 | M30: 0.19478952 | N30: 0 | O30: 0.39524702 | Q30: Trenčiansky kraj | R30: 0.72548897 | S30: 0.557 | T30: 0.32783848 | U30: 0.19295883 | V30: 0.025 | W30: 0.39524702 | Y30: Trenčiansky kraj | Z30: 0.72548897 | AA30: 0.557 | AB30: 0.32628455 | AC30: 0.19113394 | AD30: 0.05 | AE30: 0.39524702 | AG30: =ABS(L30-AB30) -> 0.003105438 | AH30: =ABS(M30-AC30) -> 0.0036555775
A31: Nitriansky kraj | B31: 0.76738065 | C31: 0.617 | D31: =G31 -> 0.50379027 | E31: 0.33759369 | F31: 0.24971745 | G31: 0.50379027 | I31: Nitriansky kraj | J31: 0.76738065 | K31: 0.617 | L31: 0.46918101 | M31: 0.35677604 | N31: 0 | O31: 0.50379027 | Q31: Nitriansky kraj | R31: 0.76738065 | S31: 0.617 | T31: 0.46790674 | U31: 0.35484071 | V31: 0.025 | W31: 0.50379027 | Y31: Nitriansky kraj | Z31: 0.76738065 | AA31: 0.617 | AB31: 0.46663118 | AC31: 0.35290868 | AD31: 0.05 | AE31: 0.50379027 | AG31: =ABS(L31-AB31) -> 0.0025498316 | AH31: =ABS(M31-AC31) -> 0.0038673638
A32: Žilinský kraj | B32: 0.75952613 | C32: 0.289 | D32: =G32 -> 0.2382463 | E32: 0.16170053 | F32: 0.12095344 | G32: 0.2382463 | I32: Žilinský kraj | J32: 0.75952613 | K32: 0.289 | L32: 0.22217235 | M32: 0.17079776 | N32: 0 | O32: 0.2382463 | Q32: Žilinský kraj | R32: 0.75952613 | S32: 0.289 | T32: 0.22093773 | U32: 0.16890477 | V32: 0.025 | W32: 0.2382463 | Y32: Žilinský kraj | Z32: 0.75952613 | AA32: 0.289 | AB32: 0.21970048 | AC32: 0.16701834 | AD32: 0.05 | AE32: 0.2382463 | AG32: =ABS(L32-AB32) -> 0.0024718691 | AH32: =ABS(M32-AC32) -> 0.0037794179
A33: Banskobystrický kraj | B33: 0.80165913 | C33: 0.481 | D33: =G33 -> 0.37116588 | E33: 0.21317931 | F33: 0.14192047 | G33: 0.37116588 | I33: Banskobystrický kraj | J33: 0.80165913 | K33: 0.481 | L33: 0.32776546 | M33: 0.2233476 | N33: 0 | O33: 0.37116588 | Q33: Banskobystrický kraj | R33: 0.80165913 | S33: 0.481 | T33: 0.32644029 | U33: 0.22154524 | V33: 0.025 | W33: 0.37116588 | Y33: Banskobystrický kraj | Z33: 0.80165913 | AA33: 0.481 | AB33: 0.32511323 | AC33: 0.21974763 | AD33: 0.05 | AE33: 0.37116588 | AG33: =ABS(L33-AB33) -> 0.0026522334 | AH33: =ABS(M33-AC33) -> 0.0035999723
A34: Prešovský kraj | B34: 0.72395013 | C34: 0.306 | D34: =G34 -> 0.24239224 | E34: 0.14657779 | F34: 0.10144754 | G34: 0.24239224 | I34: Prešovský kraj | J34: 0.72395013 | K34: 0.306 | L34: 0.21744929 | M34: 0.15452351 | N34: 0 | O34: 0.24239224 | Q34: Prešovský kraj | R34: 0.72395013 | S34: 0.306 | T34: 0.21605829 | U34: 0.1525529 | V34: 0.025 | W34: 0.24239224 | Y34: Prešovský kraj | Z34: 0.72395013 | AA34: 0.306 | AB34: 0.2146641 | AC34: 0.15059044 | AD34: 0.05 | AE34: 0.24239224 | AG34: =ABS(L34-AB34) -> 0.0027851964 | AH34: =ABS(M34-AC34) -> 0.003933074
A35: Košický kraj | B35: 0.5534179 | C35: 0.522 | D35: =G35 -> 0.43265938 | E35: 0.2991733 | F35: 0.22648998 | G35: 0.43265938 | I35: Košický kraj | J35: 0.5534179 | K35: 0.522 | L35: 0.40904975 | M35: 0.32053965 | N35: 0 | O35: 0.43265938 | Q35: Košický kraj | R35: 0.5534179 | S35: 0.522 | T35: 0.40752785 | U35: 0.31815891 | V35: 0.025 | W35: 0.43265938 | Y35: Košický kraj | Z35: 0.5534179 | AA35: 0.522 | AB35: 0.40600378 | AC35: 0.31578366 | AD35: 0.05 | AE35: 0.43265938 | AG35: =ABS(L35-AB35) -> 0.0030459706 | AH35: =ABS(M35-AC35) -> 0.0047559944
Y36: Priemerná absolútna zmena | AD36: maximálna zmena
Y37: veková skupina | Z37: priemerná absolútna zmena | AD37: maximálna zmena
Y38: 65-74 | Z38: =AVERAGE(AG28:AG35) -> 0.0029408118 | AD38: =MAX(AG28:AG35) -> 0.004440352
A39: Tab.3: Podiel žien, ktoré neboli obmedzované kvôli zdravotnému problému v činnostiach, ktoré bežne vykonávajú, podľa krajov SR, EU SILC 2024 | Y39: 75-84 | Z39: =AVERAGE(AH28:AH35) -> 0.003696356 | AD39: =MAX(AH28:AH35) -> 0.0047559944
I40: Scenár: podiel vo veku 85+ = 0 % | Q40: Scenár: podiel vo veku 85+ = 2,5 % | Y40: Scenár: podiel vo veku 85+ = 5 %
A41: Vôbec neobmedzovaný Kraj | B41: Podiel (v %) - Ženy vo veku | I41: Vôbec neobmedzovaný | J41: Podiel (v %) – ženy vo veku | Q41: Vôbec neobmedzovaný | R41: Podiel (v %) – ženy vo veku | Y41: Vôbec neobmedzovaný | Z41: Podiel (v %) – ženy vo veku
...

Sheet 4.2 HLY kraje_2024_m_ž
A1: Muži | B1: Počet obyvateľov k 31. 12. | F1: Počet zomretých v roku | I1: Obdobie: 2024 | O1: Healthy
B2: 2021 | C2: 2022 | D2: 2023 | E2: 2024 | F2: 2022 | G2: 2023 | H2: 2024 | I2: qx | J2: lx | K2: dx | L2: L*x | M2: Tx | N2: ex | O2: nLx | P2: Tx | Q2: HLEx
A4: Bratislavský kraj
A5: 0 | B5: 4232 | C5: 3822 | D5: 3465 | E5: 3103 | F5: 12 | G5: 14 | H5: 9 | I5: 0.0033686237 | J5: 100000 | K5: 336.86237 | L5: 99696.824 | M5: 7711867 | N5: 77.11867
A6: 1-4 | B6: 18393 | C6: 17990 | D6: 17052 | E6: 16063 | F6: 2 | G6: 0 | H6: 0 | I6: 0.00015303975 | J6: 99663.138 | K6: 15.252422 | L6: 99655.511 | M6: 7612170.2 | N6: 76.378994
A7: 5-9 | B7: 21917 | C7: 22365 | D7: 23069 | E7: 23200 | F7: 1 | G7: 4 | H7: 0 | I7: 0.0001027297 | J7: 99647.885 | K7: 10.236797 | L7: 99642.767 | M7: 7213548.1 | N7: 72.390379
A8: 10-14 | B8: 18744 | C8: 19560 | D8: 20045 | E8: 20560 | F8: 2 | G8: 3 | H8: 4 | I8: 0.00083585164 | J8: 99637.648 | K8: 83.282292 | L8: 99596.007 | M8: 6715334.3 | N8: 67.397559
A9: 15-19 | B9: 14197 | C9: 15113 | D9: 16051 | E9: 17085 | F9: 7 | G9: 4 | H9: 5 | I9: 0.0015973005 | J9: 99554.366 | K9: 159.01824 | L9: 99474.857 | M9: 6217354.3 | N9: 62.451849
A10: 20-24 | B10: 13056 | C10: 12847 | D10: 12977 | E10: 13386 | F10: 3 | G10: 9 | H10: 8 | I10: 0.0028341955 | J10: 99395.348 | K10: 281.70585 | L10: 99254.495 | M10: 5719980 | N10: 57.547764
A11: 25-29 | B11: 17992 | C11: 16859 | D11: 15739 | E11: 15065 | F11: 7 | G11: 17 | H11: 17 | I11: 0.0035839834 | J11: 99113.642 | K11: 355.22165 | L11: 98936.031 | M11: 5223707.5 | N11: 52.704223
A12: 30-34 | B12: 27645 | C12: 26884 | D12: 25812 | E12: 24267 | F12: 26 | G12: 18 | H12: 13 | I12: 0.0041329937 | J12: 98758.42 | K12: 408.16793 | L12: 98554.336 | M12: 4729027.4 | N12: 47.884802
A13: 35-39 | B13: 33620 | C13: 32966 | D13: 32444 | E13: 31730 | F13: 37 | G13: 38 | H13: 41 | I13: 0.0056046127 | J13: 98350.252 | K13: 551.21507 | L13: 98074.645 | M13: 4236255.7 | N13: 43.073155 | P13: keby sa pre vek od 55 rokov počítalo s nasledujúcimi konštantami 1-πx
A14: 40-44 | B14: 35601 | C14: 35436 | D14: 35208 | E14: 34632 | F14: 59 | G14: 72 | H14: 60 | I14: 0.0089393962 | J14: 97799.037 | K14: 874.26434 | L14: 97361.905 | M14: 3745882.5 | N14: 38.301834 | T14: 1-πx
A15: 45-49 | B15: 30414 | C15: 32415 | D15: 34001 | E15: 35301 | F15: 95 | G15: 99 | H15: 104 | I15: 0.01512277 | J15: 96924.773 | K15: 1465.771 | L15: 96191.888 | M15: 3259072.9 | N15: 33.624767 | O15: =$T15*L15*5 -> 349722.66 | P15: =SUM(O15:O$23) -> 1556644.3 | Q15: =P15/J15 -> 16.060335 | S15: 45-54 | T15: ='nový výpočet'!R28 -> 0.72713545
A16: 50-54 | B16: 21571 | C16: 22856 | D16: 24444 | E16: 26353 | F16: 119 | G16: 120 | H16: 142 | I16: 0.026390517 | J16: 95459.002 | K16: 2519.2124 | L16: 94199.396 | M16: 2778113.5 | N16: 29.102687 | O16: =$T15*L16*5 -> 342478.6 | P16: =SUM(O16:O$23) -> 1206921.6 | Q16: =P16/J16 -> 12.643351 | R16: AAI 4.2 | S16: 55-64 | T16: ='nový výpočet'!S28 -> 0.772
A17: 55-59 | B17: 19728 | C17: 19528 | D17: 19418 | E17: 19531 | F17: 206 | G17: 146 | H17: 166 | I17: 0.042070945 | J17: 92939.79 | K17: 3910.0648 | L17: 90984.757 | M17: 2307116.5 | N17: 24.823776 | O17: =$T16*L17*5 -> 351201.16 | P17: =SUM(O17:O$23) -> 864443.03 | Q17: =P17/J17 -> 9.3011081 | R17: =(AVERAGE(Q16:Q17)/AVERAGE(N16:N17)) -> 0.40693302 | S17: 65-74 | T17: ='nový výpočet'!T28 -> 0.20436303
A18: 60-64 | B18: 19233 | C18: 18777 | D18: 18735 | E18: 18811 | F18: 277 | G18: 251 | H18: 236 | I18: 0.067888532 | J18: 89029.725 | K18: 6044.0974 | L18: 86007.676 | M18: 1852192.7 | N18: 20.804206 | O18: =$T16*L18*5 -> 331989.63 | P18: =SUM(O18:O$23) -> 513241.87 | Q18: =P18/J18 -> 5.7648372 | S18: 75-84 | T18: ='nový výpočet'!U28 -> 0.054098769
A19: 65-69 | B19: 20196 | C19: 19950 | D19: 19358 | E19: 18793 | F19: 497 | G19: 457 | H19: 401 | I19: 0.10612304 | J19: 82985.627 | K19: 8806.6868 | L19: 78582.284 | M19: 1422154.3 | N19: 17.137357 | O19: =T17*L19*5 -> 80296.57 | P19: =SUM(O19:O$23) -> 181252.24 | Q19: =P19/J19 -> 2.1841401 | S19: 85+ | T19: ='nový výpočet'!V28 -> 0.025
A20: 70-74 | B20: 14932 | C20: 15646 | D20: 16316 | E20: 16976 | F20: 571 | G20: 548 | H20: 505 | I20: 0.15630188 | J20: 74178.941 | K20: 11594.308 | L20: 68381.787 | M20: 1029242.9 | N20: 13.875136 | O20: =T17*L20*5 -> 69873.547 | P20: =SUM(O20:O$23) -> 100955.67 | Q20: =P20/J20 -> 1.3609748
A21: 75-79 | B21: 8540 | C21: 9157 | D21: 9891 | E21: 10486 | F21: 483 | G21: 458 | H21: 530 | I21: 0.22675504 | J21: 62584.633 | K21: 14191.381 | L21: 55488.942 | M21: 687333.99 | N21: 10.982472 | O21: =T18*L21*5 -> 15009.417 | P21: =SUM(O21:O$23) -> 31082.123 | Q21: =P21/J21 -> 0.49664146
A22: 80-84 | B22: 4749 | C22: 5022 | D22: 5259 | E22: 5603 | F22: 457 | G22: 417 | H22: 416 | I22: 0.34525211 | J22: 48393.252 | K22: 16707.872 | L22: 40039.316 | M22: 409889.28 | N22: 8.4699677 | O22: =T18*L22*5 -> 10830.388 | P22: =SUM(O22:O$23) -> 16072.706 | Q22: =P22/J22 -> 0.33212701
A23: 85+ | B23: 3539 | C23: 3529 | D23: 3787 | E23: 3933 | F23: 601 | G23: 497 | H23: 572 | I23: 0.54836803 | J23: 31685.379 | K23: 31685.379 | L23: 209692.7 | M23: 209692.7 | N23: 6.6179641 | O23: =T19*L23 -> 5242.3175 | P23: =SUM(O23:O$23) -> 5242.3175 | Q23: =P23/J23 -> 0.1654491
B26: Počet obyvateľov k 31. 12. | F26: Počet zomretých v roku | I26: Obdobie: 2024
A27: Trnavský kraj | B27: 2021 | C27: 2022 | D27: 2023 | E27: 2024 | F27: 2022 | G27: 2023 | H27: 2024 | I27: qx | J27: lx | K27: dx | L27: L*x | M27: Tx | N27: ex
A28: 0 | B28: 2775 | C28: 2604 | D28: 2449 | E28: 2179 | F28: 8 | G28: 4 | H28: 5 | I28: 0.0023506637 | J28: 100000 | K28: 235.06637 | L28: 99788.44 | M28: 7468842.4 | N28: 74.688424
A29: 1-4 | B29: 11785 | C29: 11654 | D29: 11341 | E29: 10938 | F29: 1 | G29: 0 | H29: 3 | I29: 0.00046559676 | J29: 99764.934 | K29: 46.45023 | L29: 99741.709 | M29: 7369054 | N29: 73.86417
A30: 5-9 | B30: 14722 | C30: 14915 | D30: 15089 | E30: 15197 | F30: 2 | G30: 2 | H30: 2 | I30: 0.00039412887 | J30: 99718.483 | K30: 39.301934 | L30: 99698.832 | M30: 6970087.1 | N30: 69.897645
A31: 10-14 | B31: 13943 | C31: 14317 | D31: 14482 | E31: 14514 | F31: 1 | G31: 4 | H31: 1 | I31: 0.00094154256 | J31: 99679.181 | K31: 93.852191 | L31: 99632.255 | M31: 6471593 | N31: 64.924219
A32: 15-19 | B32: 12746 | C32: 12924 | D32: 13278 | E32: 13556 | F32: 2 | G32: 8 | H32: 6 | I32: 0.0018358872 | J32: 99585.329 | K32: 182.82743 | L32: 99493.916 | M32: 5973431.7 | N32: 59.983049
A33: 20-24 | B33: 13499 | C33: 13051 | D33: 12694 | E33: 12658 | F33: 9 | G33: 4 | H33: 9 | I33: 0.002870072 | J33: 99402.502 | K33: 285.29234 | L33: 99259.856 | M33: 5475962.1 | N33: 55.088776
A34: 25-29 | B34: 17029 | C34: 16157 | D34: 15293 | E34: 14540 | F34: 12 | G34: 14 | H34: 11 | I34: 0.0039418381 | J34: 99117.21 | K34: 390.70399 | L34: 98921.858 | M34: 4979662.9 | N34: 50.240144
A35: 30-34 | B35: 20768 | C35: 20328 | D35: 19919 | E35: 19434 | F35: 20 | G35: 20 | H35: 27 | I35: 0.0053550007 | J35: 98726.506 | K35: 528.68051 | L35: 98462.165 | M35: 4485053.6 | N35: 45.429072
A36: 35-39 | B36: 23147 | C36: 22684 | D36: 22267 | E36: 21710 | F36: 35 | G36: 33 | H36: 34 | I36: 0.0076938482 | J36: 98197.825 | K36: 755.51916 | L36: 97820.065 | M36: 3992742.7 | N36: 40.660195 | T36: 1-πx
A37: 40-44 | B37: 25098 | C37: 24709 | D37: 24295 | E37: 23856 | F37: 68 | G37: 57 | H37: 56 | I37: 0.012316157 | J37: 97442.306 | K37: 1200.1147 | L37: 96842.248 | M37: 3503642.4 | N37: 35.95607 | S37: 45-54 | T37: ='nový výpočet'!R29 -> 0.70126634
A38: 45-49 | B38: 24581 | C38: 25281 | D38: 25616 | E38: 25652 | F38: 101 | G38: 107 | H38: 98 | I38: 0.019005292 | J38: 96242.191 | K38: 1829.1109 | L38: 95327.636 | M38: 3019431.2 | N38: 31.373259 | O38: =T37*L38*5 -> 334250.31 | P38: =SUM(O38:O$46) -> 1359561.6 | Q38: =P38/J38 -> 14.126461 | S38: 55-64 | T38: ='nový výpočet'!S29 -> 0.433
A39: 50-54 | B39: 19356 | C39: 20037 | D39: 21087 | E39: 22099 | F39: 110 | G39: 134 | H39: 132 | I39: 0.031174454 | J39: 94413.08 | K39: 2943.2762 | L39: 92941.442 | M39: 2542793 | N39: 26.932635 | O39: =T37*L39*5 -> 325883.53 | P39: =SUM(O39:O$46) -> 1025311.3 | Q39: =P39/J39 -> 10.859844 | R39: AAI 4.2 | S39: 65-74 | T39: ='nový výpočet'!T29 -> 0.31733304
A40: 55-59 | B40: 18554 | C40: 18429 | D40: 18271 | E40: 18199 | F40: 231 | G40: 190 | H40: 194 | I40: 0.054610386 | J40: 91469.804 | K40: 4995.2013 | L40: 88972.203 | M40: 2078085.8 | N40: 22.718817 | O40: =T38*L40*5 -> 192624.82 | P40: =SUM(O40:O$46) -> 699427.77 | Q40: =P40/J40 -> 7.6465428 | R40: =(AVERAGE(Q39:Q40)/AVERAGE(N39:N40)) -> 0.37272599 | S40: 75-84 | T40: ='nový výpočet'!U29 -> 0.23256411
A41: 60-64 | B41: 17690 | C41: 17406 | D41: 17223 | E41: 17497 | F41: 376 | G41: 306 | H41: 286 | I41: 0.086598569 | J41: 86474.603 | K41: 7488.5768 | L41: 82730.314 | M41: 1633224.8 | N41: 18.886757 | O41: =T38*L41*5 -> 179111.13 | P41: =SUM(O41:O$46) -> 506802.95 | Q41: =P41/J41 -> 5.8607144 | S41: 85+ | T41: ='nový výpočet'!V29 -> 0.025
A42: 65-69 | B42: 16833 | C42: 16897 | D42: 16882 | E42: 16563 | F42: 483 | G42: 441 | H42: 416 | I42: 0.12354882 | J42: 78986.026 | K42: 9758.6305 | L42: 74106.711 | M42: 1219573.2 | N42: 15.440367 | O42: =T39*L42*5 -> 117582.54 | P42: =SUM(O42:O$46) -> 327691.82 | Q42: =P42/J42 -> 4.1487316
A43: 70-74 | B43: 12004 | C43: 12639 | D43: 13238 | E43: 13829 | F43: 514 | G43: 524 | H43: 505 | I43: 0.18726576 | J43: 69227.395 | K43: 12963.92 | L43: 62745.435 | M43: 849039.64 | N43: 12.264504 | O43: =T39*L43*5 -> 99555.999 | P43: =SUM(O43:O$46) -> 210109.28 | Q43: =P43/J43 -> 3.0350597
...
